Workbook
Name CalendarYear: 'Itinerary Calendar'!$F$3
Name CalendarYear: 'Itinerary-CODE'!$K$2
Name ColumnTitleRegion1..H12.1: 'Itinerary Calendar'!$B$11
Name ColumnTitleRegion1..H12.1: #REF!
Name ColumnTitleRegion2..C14.1: 'Itinerary Calendar'!$B$11
Name ColumnTitleRegion2..C14.1: #REF!
Name DaysAndWeeks: {0,1,2,3,4,5,6} + {0;1;2;3;4;5}*7
Name DaysAndWeeks: {0,1,2,3,4,5,6} + {0;1;2;3;4;5}*7
Name DaysAndWeeks1: {0,1,2,3,4,5,6} + {0;1;2;3;4;5}*7
Name DreamStartDate: '#1 Trip Dreaming'!$E$3
Name DreamStartMonth: 'Itinerary Calendar'!$H$3
Name DreamStartMonth2: 'Itinerary Calendar'!$N$2
Name DreamStartMonth3: 'Itinerary Calendar'!$N$3
Name DreamStartYear: 'Itinerary Calendar'!$G$3
Name RowTitleRegion1..K3: 'Itinerary Calendar'!$J$11
Name RowTitleRegion1..K3: #REF!
Name WeekStart: 'Itinerary Calendar'!#REF!
Name WeekStart: 'Itinerary-CODE'!$K$3
Name WeekStart1: 'Itinerary-CODE'!$H$3

Sheet Directory
A1: Solo Trip Planner Directory
A2: Put together by swelltravels.xlsx

Sheet Dashboard

Sheet #1 Trip Dreaming
B1: Trip Dreaming | J1: Dream Outline
B2: This is the spot to put down all of those places you want to go… and how long you want to stay there. | J2: No need to put anything over here. It will appear magically.
B3: Trip Start Date | E3: 45071 | F3: *double check this PLEASE (MM/DD/YYYY) | J3: Total # of Days | L3: =SUM(D6:D30) -> 9
B5: Stop on Trip | D5: Days in Location | E5: City | F5: Country | G5: Preferred Month | H5: Average Room Cost | J5: Stop | K5: Start Date | L5: End Date | M5: Location | N5: # Days
B6: # | C6: 1 | D6: 2 | E6: Barcelona | F6: Spain | J6: 1 | K6: =IFERROR(E3," ") -> 45071 | L6: =IFERROR(IF(J6=C6,K6+D6,K6+VLOOKUP(J6,$C$6:$D$30,2,FALSE))," ") -> 45073 | M6: =IFERROR(IF(N6=0," ",IF(J6=C6,CONCATENATE(E6,", ",F6),CONCATENATE(VLOOKUP(J6,$C$6:$F$30,3,FALSE),", ",VLOOKUP(J6,$C$6:$F$30,4,FALSE))))," ") -> Barcelona, Spain | N6: =IFERROR(VLOOKUP(J6,$C$6:$F$30,2,FALSE)," ") -> 2
B7: # | C7: 2 | D7: 4 | E7: Mallorca | F7: Spain | J7: 2 | K7: =IFERROR(IF(N6=0," ",L6)," ") -> 45073 | L7: =IFERROR(IF(J7=C7,K7+D7,K7+VLOOKUP(J7,$C$6:$D$30,2,FALSE))," ") -> 45077 | M7: =IFERROR(IF(N7=0," ",IF(J7=C7,CONCATENATE(E7,", ",F7),CONCATENATE(VLOOKUP(J7,$C$6:$F$30,3,FALSE),", ",VLOOKUP(J7,$C$6:$F$30,4,FALSE))))," ") -> Mallorca, Spain | N7: =IFERROR(VLOOKUP(J7,$C$6:$F$30,2,FALSE)," ") -> 4
B8: # | C8: 3 | D8: 2 | E8: Ibiza | F8: Spain | J8: 3 | K8: =IFERROR(IF(N7=0," ",L7)," ") -> 45077 | L8: =IFERROR(IF(J8=C8,K8+D8,K8+VLOOKUP(J8,$C$6:$D$30,2,FALSE))," ") -> 45079 | M8: =IFERROR(IF(N8=0," ",IF(J8=C8,CONCATENATE(E8,", ",F8),CONCATENATE(VLOOKUP(J8,$C$6:$F$30,3,FALSE),", ",VLOOKUP(J8,$C$6:$F$30,4,FALSE))))," ") -> Ibiza, Spain | N8: =IFERROR(VLOOKUP(J8,$C$6:$F$30,2,FALSE)," ") -> 2
B9: # | C9: 4 | D9: 1 | E9: Barcelona | F9: Spain | J9: 4 | K9: =IFERROR(IF(N8=0," ",L8)," ") -> 45079 | L9: =IFERROR(IF(J9=C9,K9+D9,K9+VLOOKUP(J9,$C$6:$D$30,2,FALSE))," ") -> 45080 | M9: =IFERROR(IF(N9=0," ",IF(J9=C9,CONCATENATE(E9,", ",F9),CONCATENATE(VLOOKUP(J9,$C$6:$F$30,3,FALSE),", ",VLOOKUP(J9,$C$6:$F$30,4,FALSE))))," ") -> Barcelona, Spain | N9: =IFERROR(VLOOKUP(J9,$C$6:$F$30,2,FALSE)," ") -> 1
B10: # | C10: 5 | J10: 5 | K10: =IFERROR(IF(N9=0," ",L9)," ") -> 45080 | L10: =IFERROR(IF(J10=C10,K10+D10,K10+VLOOKUP(J10,$C$6:$D$30,2,FALSE))," ") -> 45080 | M10: =IFERROR(IF(N10=0," ",IF(J10=C10,CONCATENATE(E10,", ",F10),CONCATENATE(VLOOKUP(J10,$C$6:$F$30,3,FALSE),", ",VLOOKUP(J10,$C$6:$F$30,4,FALSE))))," ") | N10: =IFERROR(VLOOKUP(J10,$C$6:$F$30,2,FALSE)," ") -> 0
B11: # | C11: 6 | J11: 6 | K11: =IFERROR(IF(N10=0," ",L10)," ") | L11: =IFERROR(IF(J11=C11,K11+D11,K11+VLOOKUP(J11,$C$6:$D$30,2,FALSE))," ") | M11: =IFERROR(IF(N11=0," ",IF(J11=C11,CONCATENATE(E11,", ",F11),CONCATENATE(VLOOKUP(J11,$C$6:$F$30,3,FALSE),", ",VLOOKUP(J11,$C$6:$F$30,4,FALSE))))," ") | N11: =IFERROR(VLOOKUP(J11,$C$6:$F$30,2,FALSE)," ") -> 0
B12: # | C12: 7 | J12: 7 | K12: =IFERROR(IF(N11=0," ",L11)," ") | L12: =IFERROR(IF(J12=C12,K12+D12,K12+VLOOKUP(J12,$C$6:$D$30,2,FALSE))," ") | M12: =IFERROR(IF(N12=0," ",IF(J12=C12,CONCATENATE(E12,", ",F12),CONCATENATE(VLOOKUP(J12,$C$6:$F$30,3,FALSE),", ",VLOOKUP(J12,$C$6:$F$30,4,FALSE))))," ") | N12: =IFERROR(VLOOKUP(J12,$C$6:$F$30,2,FALSE)," ") -> 0
B13: # | C13: 8 | J13: 8 | K13: =IFERROR(IF(N12=0," ",L12)," ") | L13: =IFERROR(IF(J13=C13,K13+D13,K13+VLOOKUP(J13,$C$6:$D$30,2,FALSE))," ") | M13: =IFERROR(IF(N13=0," ",IF(J13=C13,CONCATENATE(E13,", ",F13),CONCATENATE(VLOOKUP(J13,$C$6:$F$30,3,FALSE),", ",VLOOKUP(J13,$C$6:$F$30,4,FALSE))))," ") | N13: =IFERROR(VLOOKUP(J13,$C$6:$F$30,2,FALSE)," ") -> 0
B14: # | C14: 9 | J14: 9 | K14: =IFERROR(IF(N13=0," ",L13)," ") | L14: =IFERROR(IF(J14=C14,K14+D14,K14+VLOOKUP(J14,$C$6:$D$30,2,FALSE))," ") | M14: =IFERROR(IF(N14=0," ",IF(J14=C14,CONCATENATE(E14,", ",F14),CONCATENATE(VLOOKUP(J14,$C$6:$F$30,3,FALSE),", ",VLOOKUP(J14,$C$6:$F$30,4,FALSE))))," ") | N14: =IFERROR(VLOOKUP(J14,$C$6:$F$30,2,FALSE)," ") -> 0
B15: # | C15: 10 | J15: 10 | K15: =IFERROR(IF(N14=0," ",L14)," ") | L15: =IFERROR(IF(J15=C15,K15+D15,K15+VLOOKUP(J15,$C$6:$D$30,2,FALSE))," ") | M15: =IFERROR(IF(N15=0," ",IF(J15=C15,CONCATENATE(E15,", ",F15),CONCATENATE(VLOOKUP(J15,$C$6:$F$30,3,FALSE),", ",VLOOKUP(J15,$C$6:$F$30,4,FALSE))))," ") | N15: =IFERROR(VLOOKUP(J15,$C$6:$F$30,2,FALSE)," ") -> 0
B16: # | C16: 11 | J16: 11 | K16: =IFERROR(IF(N15=0," ",L15)," ") | L16: =IFERROR(IF(J16=C16,K16+D16,K16+VLOOKUP(J16,$C$6:$D$30,2,FALSE))," ") | M16: =IFERROR(IF(N16=0," ",IF(J16=C16,CONCATENATE(E16,", ",F16),CONCATENATE(VLOOKUP(J16,$C$6:$F$30,3,FALSE),", ",VLOOKUP(J16,$C$6:$F$30,4,FALSE))))," ") | N16: =IFERROR(VLOOKUP(J16,$C$6:$F$30,2,FALSE)," ") -> 0
B17: # | C17: 12 | J17: 12 | K17: =IFERROR(IF(N16=0," ",L16)," ") | L17: =IFERROR(IF(J17=C17,K17+D17,K17+VLOOKUP(J17,$C$6:$D$30,2,FALSE))," ") | M17: =IFERROR(IF(N17=0," ",IF(J17=C17,CONCATENATE(E17,", ",F17),CONCATENATE(VLOOKUP(J17,$C$6:$F$30,3,FALSE),", ",VLOOKUP(J17,$C$6:$F$30,4,FALSE))))," ") | N17: =IFERROR(VLOOKUP(J17,$C$6:$F$30,2,FALSE)," ") -> 0
B18: # | C18: 13 | J18: 13 | K18: =IFERROR(IF(N17=0," ",L17)," ") | L18: =IFERROR(IF(J18=C18,K18+D18,K18+VLOOKUP(J18,$C$6:$D$30,2,FALSE))," ") | M18: =IFERROR(IF(N18=0," ",IF(J18=C18,CONCATENATE(E18,", ",F18),CONCATENATE(VLOOKUP(J18,$C$6:$F$30,3,FALSE),", ",VLOOKUP(J18,$C$6:$F$30,4,FALSE))))," ") | N18: =IFERROR(VLOOKUP(J18,$C$6:$F$30,2,FALSE)," ") -> 0
B19: # | C19: 14 | J19: 14 | K19: =IFERROR(IF(N18=0," ",L18)," ") | L19: =IFERROR(IF(J19=C19,K19+D19,K19+VLOOKUP(J19,$C$6:$D$30,2,FALSE))," ") | M19: =IFERROR(IF(N19=0," ",IF(J19=C19,CONCATENATE(E19,", ",F19),CONCATENATE(VLOOKUP(J19,$C$6:$F$30,3,FALSE),", ",VLOOKUP(J19,$C$6:$F$30,4,FALSE))))," ") | N19: =IFERROR(VLOOKUP(J19,$C$6:$F$30,2,FALSE)," ") -> 0
B20: # | C20: 15 | J20: 15 | K20: =IFERROR(IF(N19=0," ",L19)," ") | L20: =IFERROR(IF(J20=C20,K20+D20,K20+VLOOKUP(J20,$C$6:$D$30,2,FALSE))," ") | M20: =IFERROR(IF(N20=0," ",IF(J20=C20,CONCATENATE(E20,", ",F20),CONCATENATE(VLOOKUP(J20,$C$6:$F$30,3,FALSE),", ",VLOOKUP(J20,$C$6:$F$30,4,FALSE))))," ") | N20: =IFERROR(VLOOKUP(J20,$C$6:$F$30,2,FALSE)," ") -> 0
B21: # | C21: 16 | J21: 16 | K21: =IFERROR(IF(N20=0," ",L20)," ") | L21: =IFERROR(IF(J21=C21,K21+D21,K21+VLOOKUP(J21,$C$6:$D$30,2,FALSE))," ") | M21: =IFERROR(IF(N21=0," ",IF(J21=C21,CONCATENATE(E21,", ",F21),CONCATENATE(VLOOKUP(J21,$C$6:$F$30,3,FALSE),", ",VLOOKUP(J21,$C$6:$F$30,4,FALSE))))," ") | N21: =IFERROR(VLOOKUP(J21,$C$6:$F$30,2,FALSE)," ") -> 0
... B30: # | C30: 25 | J30: 25 | K30: =IFERROR(IF(N29=0," ",L29)," ") | L30: =IFERROR(IF(J30=C30,K30+D30,K30+VLOOKUP(J30,$C$6:$D$30,2,FALSE))," ") | M30: =IFERROR(IF(N30=0," ",IF(J30=C30,CONCATENATE(E30,", ",F30),CONCATENATE(VLOOKUP(J30,$C$6:$F$30,3,FALSE),", ",VLOOKUP(J30,$C$6:$F$30,4,FALSE))))," ") | N30: =IFERROR(VLOOKUP(J30,$C$6:$F$30,2,FALSE)," ") -> 0

Sheet Itinerary Calendar
B1: Trip Itinerary Calendar | F1: Auto Calendar Settings
B2: This is where you can find the calendar plan of your trip. | F2: Start Date | G2: Year Start | H2: Month # Start | M2: Start Month 2 | N2: =IF((DreamStartMonth+1)<=12,DreamStartMonth+1,1) -> 6
F3: =DreamStartDate -> 45071 | G3: =YEAR(DreamStartDate) -> 2023 | H3: =MONTH(DreamStartDate) -> 5 | M3: Start Month 3 | N3: =IF((DreamStartMonth+2)<=12,DreamStartMonth+2,IF((DreamStartMonth+2)<=13,1,2)) -> 7
B5: Friday
B6: 1 Location Accomodation for that night
B7: TRAVEL DAY
B8: Day Plan/Activities
B9: *Choose the contents you want
B10: {=(_xlfn.IFS(H3=1,"January ",H3=2,"February ",H3=3,"March ",H3=4,"April ",H3=5,"May ",H3=6,"June ",H3=7,"July ",H3=8,"August ",H3=9,"September ",H3=10,"October ",H3=11,"November ",H3=12,"December "))&YEAR(B17)} -> May 2023
B11: Sunday | C11: Monday | D11: Tuesday | E11: Wednesday | F11: Thursday | G11: Friday | H11: Saturday
B12: ='Itinerary-CODE'!B4 | C12: ='Itinerary-CODE'!C4 -> 45047 | D12: ='Itinerary-CODE'!D4 -> 45048 | E12: ='Itinerary-CODE'!E4 -> 45049 | F12: ='Itinerary-CODE'!F4 -> 45050 | G12: ='Itinerary-CODE'!G4 -> 45051 | H12: ='Itinerary-CODE'!H4 -> 45052
B13: =IFERROR(VLOOKUP(B12,Itinerary!$B$9:$E$108,2,FALSE)," ") | C13: =IFERROR(VLOOKUP(C12,Itinerary!$B$9:$E$108,2,FALSE)," ") | D13: =IFERROR(VLOOKUP(D12,Itinerary!$B$9:$E$108,2,FALSE)," ") | E13: =IFERROR(VLOOKUP(E12,Itinerary!$B$9:$E$108,2,FALSE)," ") | F13: =IFERROR(VLOOKUP(F12,Itinerary!$B$9:$E$108,2,FALSE)," ") | G13: =IFERROR(VLOOKUP(G12,Itinerary!$B$9:$E$108,2,FALSE)," ") | H13: =IFERROR(VLOOKUP(H12,Itinerary!$B$9:$E$108,2,FALSE)," ")
B14: =IFERROR(VLOOKUP(B12,Itinerary!$B$9:$E$108,3,FALSE)," ") | C14: =IFERROR(VLOOKUP(C12,Itinerary!$B$9:$E$108,3,FALSE)," ") | D14: =IFERROR(VLOOKUP(D12,Itinerary!$B$9:$E$108,3,FALSE)," ") | E14: =IFERROR(VLOOKUP(E12,Itinerary!$B$9:$E$108,3,FALSE)," ") | F14: =IFERROR(VLOOKUP(F12,Itinerary!$B$9:$E$108,3,FALSE)," ") | G14: =IFERROR(VLOOKUP(G12,Itinerary!$B$9:$E$108,3,FALSE)," ") | H14: =IFERROR(VLOOKUP(H12,Itinerary!$B$9:$E$108,3,FALSE)," ")
B15: =IFERROR(IF(VLOOKUP(B12,Itinerary!$B$9:$E$108,4,FALSE)="Yes","TRAVEL DAY"," ")," ") | C15: =IFERROR(IF(VLOOKUP(C12,Itinerary!$B$9:$E$108,4,FALSE)="Yes","TRAVEL DAY"," ")," ") | D15: =IFERROR(IF(VLOOKUP(D12,Itinerary!$B$9:$E$108,4,FALSE)="Yes","TRAVEL DAY"," ")," ") | E15: =IFERROR(IF(VLOOKUP(E12,Itinerary!$B$9:$E$108,4,FALSE)="Yes","TRAVEL DAY"," ")," ") | F15: =IFERROR(IF(VLOOKUP(F12,Itinerary!$B$9:$E$108,4,FALSE)="Yes","TRAVEL DAY"," ")," ") | G15: =IFERROR(IF(VLOOKUP(G12,Itinerary!$B$9:$E$108,4,FALSE)="Yes","TRAVEL DAY"," ")," ") | H15: =IFERROR(IF(VLOOKUP(H12,Itinerary!$B$9:$E$108,4,FALSE)="Yes","TRAVEL DAY"," ")," ")
B16: {=IFERROR(_xlfn.IFS($B$8="Travel Plan",VLOOKUP(B12,Table2[],5,FALSE),$B$8="Day Plan/Activities",VLOOKUP(B12,Table2[],6,FALSE),$B$8="Today's Budget",VLOOKUP(B12,Table2[],7,FALSE),$B$8="Notes",VLOOKUP(B12,Table2[],8,FALSE))," ")} | C16: {=IFERROR(_xlfn.IFS($B$8="Travel Plan",VLOOKUP(C12,Table2[],5,FALSE),$B$8="Day Plan/Activities",VLOOKUP(C12,Table2[],6,FALSE),$B$8="Today's Budget",VLOOKUP(C12,Table2[],7,FALSE),$B$8="Notes",VLOOKUP(C12,Table2[],8,FALSE))," ")} | D16: {=IFERROR(_xlfn.IFS($B$8="Travel Plan",VLOOKUP(D12,Table2[],5,FALSE),$B$8="Day Plan/Activities",VLOOKUP(D12,Table2[],6,FALSE),$B$8="Today's Budget",VLOOKUP(D12,Table2[],7,FALSE),$B$8="Notes",VLOOKUP(D12,Table2[],8,FALSE))," ")} | E16: {=IFERROR(_xlfn.IFS($B$8="Travel Plan",VLOOKUP(E12,Table2[],5,FALSE),$B$8="Day Plan/Activities",VLOOKUP(E12,Table2[],6,FALSE),$B$8="Today's Budget",VLOOKUP(E12,Table2[],7,FALSE),$B$8="Notes",VLOOKUP(E12,Table2[],8,FALSE))," ")} | F16: {=IFERROR(_xlfn.IFS($B$8="Travel Plan",VLOOKUP(F12,Table2[],5,FALSE),$B$8="Day Plan/Activities",VLOOKUP(F12,Table2[],6,FALSE),$B$8="Today's Budget",VLOOKUP(F12,Table2[],7,FALSE),$B$8="Notes",VLOOKUP(F12,Table2[],8,FALSE))," ")} | G16: {=IFERROR(_xlfn.IFS($B$8="Travel Plan",VLOOKUP(G12,Table2[],5,FALSE),$B$8="Day Plan/Activities",VLOOKUP(G12,Table2[],6,FALSE),$B$8="Today's Budget",VLOOKUP(G12,Table2[],7,FALSE),$B$8="Notes",VLOOKUP(G12,Table2[],8,FALSE))," ")} | H16: {=IFERROR(_xlfn.IFS($B$8="Travel Plan",VLOOKUP(H12,Table2[],5,FALSE),$B$8="Day Plan/Activities",VLOOKUP(H12,Table2[],6,FALSE),$B$8="Today's Budget",VLOOKUP(H12,Table2[],7,FALSE),$B$8="Notes",VLOOKUP(H12,Table2[],8,FALSE))," ")}
B17: ='Itinerary-CODE'!B5 -> 45053 | C17: ='Itinerary-CODE'!C5 -> 45054 | D17: ='Itinerary-CODE'!D5 -> 45055 | E17: ='Itinerary-CODE'!E5 -> 45056 | F17: ='Itinerary-CODE'!F5 -> 45057 | G17: ='Itinerary-CODE'!G5 -> 45058 | H17: ='Itinerary-CODE'!H5 -> 45059
B18: =IFERROR(VLOOKUP(B17,Itinerary!$B$9:$E$108,2,FALSE)," ") | C18: =IFERROR(VLOOKUP(C17,Itinerary!$B$9:$E$108,2,FALSE)," ") | D18: =IFERROR(VLOOKUP(D17,Itinerary!$B$9:$E$108,2,FALSE)," ") | E18: =IFERROR(VLOOKUP(E17,Itinerary!$B$9:$E$108,2,FALSE)," ") | F18: =IFERROR(VLOOKUP(F17,Itinerary!$B$9:$E$108,2,FALSE)," ") | G18: =IFERROR(VLOOKUP(G17,Itinerary!$B$9:$E$108,2,FALSE)," ") | H18: =IFERROR(VLOOKUP(H17,Itinerary!$B$9:$E$108,2,FALSE)," ")
B19: =IFERROR(VLOOKUP(B17,Itinerary!$B$9:$E$108,3,FALSE)," ") | C19: =IFERROR(VLOOKUP(C17,Itinerary!$B$9:$E$108,3,FALSE)," ") | D19: =IFERROR(VLOOKUP(D17,Itinerary!$B$9:$E$108,3,FALSE)," ") | E19: =IFERROR(VLOOKUP(E17,Itinerary!$B$9:$E$108,3,FALSE)," ") | F19: =IFERROR(VLOOKUP(F17,Itinerary!$B$9:$E$108,3,FALSE)," ") | G19: =IFERROR(VLOOKUP(G17,Itinerary!$B$9:$E$108,3,FALSE)," ") | H19: =IFERROR(VLOOKUP(H17,Itinerary!$B$9:$E$108,3,FALSE)," ")
B20: =IFERROR(IF(VLOOKUP(B17,Itinerary!$B$9:$E$108,4,FALSE)="Yes","TRAVEL DAY"," ")," ") | C20: =IFERROR(IF(VLOOKUP(C17,Itinerary!$B$9:$E$108,4,FALSE)="Yes","TRAVEL DAY"," ")," ") | D20: =IFERROR(IF(VLOOKUP(D17,Itinerary!$B$9:$E$108,4,FALSE)="Yes","TRAVEL DAY"," ")," ") | E20: =IFERROR(IF(VLOOKUP(E17,Itinerary!$B$9:$E$108,4,FALSE)="Yes","TRAVEL DAY"," ")," ") | F20: =IFERROR(IF(VLOOKUP(F17,Itinerary!$B$9:$E$108,4,FALSE)="Yes","TRAVEL DAY"," ")," ") | G20: =IFERROR(IF(VLOOKUP(G17,Itinerary!$B$9:$E$108,4,FALSE)="Yes","TRAVEL DAY"," ")," ") | H20: =IFERROR(IF(VLOOKUP(H17,Itinerary!$B$9:$E$108,4,FALSE)="Yes","TRAVEL DAY"," ")," ")
B21: {=IFERROR(_xlfn.IFS($B$8="Travel Plan",VLOOKUP(B17,Table2[],5,FALSE),$B$8="Day Plan/Activities",VLOOKUP(B17,Table2[],6,FALSE),$B$8="Today's Budget",VLOOKUP(B17,Table2[],7,FALSE),$B$8="Notes",VLOOKUP(B17,Table2[],8,FALSE))," ")} | C21: {=IFERROR(_xlfn.IFS($B$8="Travel Plan",VLOOKUP(C17,Table2[],5,FALSE),$B$8="Day Plan/Activities",VLOOKUP(C17,Table2[],6,FALSE),$B$8="Today's Budget",VLOOKUP(C17,Table2[],7,FALSE),$B$8="Notes",VLOOKUP(C17,Table2[],8,FALSE))," ")} | D21: {=IFERROR(_xlfn.IFS($B$8="Travel Plan",VLOOKUP(D17,Table2[],5,FALSE),$B$8="Day Plan/Activities",VLOOKUP(D17,Table2[],6,FALSE),$B$8="Today's Budget",VLOOKUP(D17,Table2[],7,FALSE),$B$8="Notes",VLOOKUP(D17,Table2[],8,FALSE))," ")} | E21: {=IFERROR(_xlfn.IFS($B$8="Travel Plan",VLOOKUP(E17,Table2[],5,FALSE),$B$8="Day Plan/Activities",VLOOKUP(E17,Table2[],6,FALSE),$B$8="Today's Budget",VLOOKUP(E17,Table2[],7,FALSE),$B$8="Notes",VLOOKUP(E17,Table2[],8,FALSE))," ")} | F21: {=IFERROR(_xlfn.IFS($B$8="Travel Plan",VLOOKUP(F17,Table2[],5,FALSE),$B$8="Day Plan/Activities",VLOOKUP(F17,Table2[],6,FALSE),$B$8="Today's Budget",VLOOKUP(F17,Table2[],7,FALSE),$B$8="Notes",VLOOKUP(F17,Table2[],8,FALSE))," ")} | G21: {=IFERROR(_xlfn.IFS($B$8="Travel Plan",VLOOKUP(G17,Table2[],5,FALSE),$B$8="Day Plan/Activities",VLOOKUP(G17,Table2[],6,FALSE),$B$8="Today's Budget",VLOOKUP(G17,Table2[],7,FALSE),$B$8="Notes",VLOOKUP(G17,Table2[],8,FALSE))," ")} | H21: {=IFERROR(_xlfn.IFS($B$8="Travel Plan",VLOOKUP(H17,Table2[],5,FALSE),$B$8="Day Plan/Activities",VLOOKUP(H17,Table2[],6,FALSE),$B$8="Today's Budget",VLOOKUP(H17,Table2[],7,FALSE),$B$8="Notes",VLOOKUP(H17,Table2[],8,FALSE))," ")}
B22: ='Itinerary-CODE'!B6 -> 45060 | C22: ='Itinerary-CODE'!C6 -> 45061 | D22: ='Itinerary-CODE'!D6 -> 45062 | E22: ='Itinerary-CODE'!E6 -> 45063 | F22: ='Itinerary-CODE'!F6 -> 45064 | G22: ='Itinerary-CODE'!G6 -> 45065 | H22: ='Itinerary-CODE'!H6 -> 45066
B23: =IFERROR(VLOOKUP(B22,Itinerary!$B$9:$E$108,2,FALSE)," ") | C23: =IFERROR(VLOOKUP(C22,Itinerary!$B$9:$E$108,2,FALSE)," ") | D23: =IFERROR(VLOOKUP(D22,Itinerary!$B$9:$E$108,2,FALSE)," ") | E23: =IFERROR(VLOOKUP(E22,Itinerary!$B$9:$E$108,2,FALSE)," ") | F23: =IFERROR(VLOOKUP(F22,Itinerary!$B$9:$E$108,2,FALSE)," ") | G23: =IFERROR(VLOOKUP(G22,Itinerary!$B$9:$E$108,2,FALSE)," ") | H23: =IFERROR(VLOOKUP(H22,Itinerary!$B$9:$E$108,2,FALSE)," ")
B24: =IFERROR(VLOOKUP(B22,Itinerary!$B$9:$E$108,3,FALSE)," ") | C24: =IFERROR(VLOOKUP(C22,Itinerary!$B$9:$E$108,3,FALSE)," ") | D24: =IFERROR(VLOOKUP(D22,Itinerary!$B$9:$E$108,3,FALSE)," ") | E24: =IFERROR(VLOOKUP(E22,Itinerary!$B$9:$E$108,3,FALSE)," ") | F24: =IFERROR(VLOOKUP(F22,Itinerary!$B$9:$E$108,3,FALSE)," ") | G24: =IFERROR(VLOOKUP(G22,Itinerary!$B$9:$E$108,3,FALSE)," ") | H24: =IFERROR(VLOOKUP(H22,Itinerary!$B$9:$E$108,3,FALSE)," ")
B25: =IFERROR(IF(VLOOKUP(B22,Itinerary!$B$9:$E$108,4,FALSE)="Yes","TRAVEL DAY"," ")," ") | C25: =IFERROR(IF(VLOOKUP(C22,Itinerary!$B$9:$E$108,4,FALSE)="Yes","TRAVEL DAY"," ")," ") | D25: =IFERROR(IF(VLOOKUP(D22,Itinerary!$B$9:$E$108,4,FALSE)="Yes","TRAVEL DAY"," ")," ") | E25: =IFERROR(IF(VLOOKUP(E22,Itinerary!$B$9:$E$108,4,FALSE)="Yes","TRAVEL DAY"," ")," ") | F25: =IFERROR(IF(VLOOKUP(F22,Itinerary!$B$9:$E$108,4,FALSE)="Yes","TRAVEL DAY"," ")," ") | G25: =IFERROR(IF(VLOOKUP(G22,Itinerary!$B$9:$E$108,4,FALSE)="Yes","TRAVEL DAY"," ")," ") | H25: =IFERROR(IF(VLOOKUP(H22,Itinerary!$B$9:$E$108,4,FALSE)="Yes","TRAVEL DAY"," ")," ")
B26: {=IFERROR(_xlfn.IFS($B$8="Travel Plan",VLOOKUP(B22,Table2[],5,FALSE),$B$8="Day Plan/Activities",VLOOKUP(B22,Table2[],6,FALSE),$B$8="Today's Budget",VLOOKUP(B22,Table2[],7,FALSE),$B$8="Notes",VLOOKUP(B22,Table2[],8,FALSE))," ")} | C26: {=IFERROR(_xlfn.IFS($B$8="Travel Plan",VLOOKUP(C22,Table2[],5,FALSE),$B$8="Day Plan/Activities",VLOOKUP(C22,Table2[],6,FALSE),$B$8="Today's Budget",VLOOKUP(C22,Table2[],7,FALSE),$B$8="Notes",VLOOKUP(C22,Table2[],8,FALSE))," ")} | D26: {=IFERROR(_xlfn.IFS($B$8="Travel Plan",VLOOKUP(D22,Table2[],5,FALSE),$B$8="Day Plan/Activities",VLOOKUP(D22,Table2[],6,FALSE),$B$8="Today's Budget",VLOOKUP(D22,Table2[],7,FALSE),$B$8="Notes",VLOOKUP(D22,Table2[],8,FALSE))," ")} | E26: {=IFERROR(_xlfn.IFS($B$8="Travel Plan",VLOOKUP(E22,Table2[],5,FALSE),$B$8="Day Plan/Activities",VLOOKUP(E22,Table2[],6,FALSE),$B$8="Today's Budget",VLOOKUP(E22,Table2[],7,FALSE),$B$8="Notes",VLOOKUP(E22,Table2[],8,FALSE))," ")} | F26: {=IFERROR(_xlfn.IFS($B$8="Travel Plan",VLOOKUP(F22,Table2[],5,FALSE),$B$8="Day Plan/Activities",VLOOKUP(F22,Table2[],6,FALSE),$B$8="Today's Budget",VLOOKUP(F22,Table2[],7,FALSE),$B$8="Notes",VLOOKUP(F22,Table2[],8,FALSE))," ")} | G26: {=IFERROR(_xlfn.IFS($B$8="Travel Plan",VLOOKUP(G22,Table2[],5,FALSE),$B$8="Day Plan/Activities",VLOOKUP(G22,Table2[],6,FALSE),$B$8="Today's Budget",VLOOKUP(G22,Table2[],7,FALSE),$B$8="Notes",VLOOKUP(G22,Table2[],8,FALSE))," ")} | H26: {=IFERROR(_xlfn.IFS($B$8="Travel Plan",VLOOKUP(H22,Table2[],5,FALSE),$B$8="Day Plan/Activities",VLOOKUP(H22,Table2[],6,FALSE),$B$8="Today's Budget",VLOOKUP(H22,Table2[],7,FALSE),$B$8="Notes",VLOOKUP(H22,Table2[],8,FALSE))," ")}
B27: ='Itinerary-CODE'!B7 -> 45067 | C27: ='Itinerary-CODE'!C7 -> 45068 | D27: ='Itinerary-CODE'!D7 -> 45069 | E27: ='Itinerary-CODE'!E7 -> 45070 | F27: ='Itinerary-CODE'!F7 -> 45071 | G27: ='Itinerary-CODE'!G7 -> 45072 | H27: ='Itinerary-CODE'!H7 -> 45073
B28: =IFERROR(VLOOKUP(B27,Itinerary!$B$9:$E$108,2,FALSE)," ") | C28: =IFERROR(VLOOKUP(C27,Itinerary!$B$9:$E$108,2,FALSE)," ") | D28: =IFERROR(VLOOKUP(D27,Itinerary!$B$9:$E$108,2,FALSE)," ") | E28: =IFERROR(VLOOKUP(E27,Itinerary!$B$9:$E$108,2,FALSE)," ") | F28: =IFERROR(VLOOKUP(F27,Itinerary!$B$9:$E$108,2,FALSE)," ") -> Barcelona, Spain | G28: =IFERROR(VLOOKUP(G27,Itinerary!$B$9:$E$108,2,FALSE)," ") -> Barcelona, Spain | H28: =IFERROR(VLOOKUP(H27,Itinerary!$B$9:$E$108,2,FALSE)," ") -> Mallorca, Spain
B29: =IFERROR(VLOOKUP(B27,Itinerary!$B$9:$E$108,3,FALSE)," ") | C29: =IFERROR(VLOOKUP(C27,Itinerary!$B$9:$E$108,3,FALSE)," ") | D29: =IFERROR(VLOOKUP(D27,Itinerary!$B$9:$E$108,3,FALSE)," ") | E29: =IFERROR(VLOOKUP(E27,Itinerary!$B$9:$E$108,3,FALSE)," ") | F29: =IFERROR(VLOOKUP(F27,Itinerary!$B$9:$E$108,3,FALSE)," ") -> TOC Hostel Barcelona | G29: =IFERROR(VLOOKUP(G27,Itinerary!$B$9:$E$108,3,FALSE)," ") -> TOC Hostel Barcelona | H29: =IFERROR(VLOOKUP(H27,Itinerary!$B$9:$E$108,3,FALSE)," ") -> El Josemari
B30: =IFERROR(IF(VLOOKUP(B27,Itinerary!$B$9:$E$108,4,FALSE)="Yes","TRAVEL DAY"," ")," ") | C30: =IFERROR(IF(VLOOKUP(C27,Itinerary!$B$9:$E$108,4,FALSE)="Yes","TRAVEL DAY"," ")," ") | D30: =IFERROR(IF(VLOOKUP(D27,Itinerary!$B$9:$E$108,4,FALSE)="Yes","TRAVEL DAY"," ")," ") | E30: =IFERROR(IF(VLOOKUP(E27,Itinerary!$B$9:$E$108,4,FALSE)="Yes","TRAVEL DAY"," ")," ") | F30: =IFERROR(IF(VLOOKUP(F27,Itinerary!$B$9:$E$108,4,FALSE)="Yes","TRAVEL DAY"," ")," ") -> TRAVEL DAY | G30: =IFERROR(IF(VLOOKUP(G27,Itinerary!$B$9:$E$108,4,FALSE)="Yes","TRAVEL DAY"," ")," ") | H30: =IFERROR(IF(VLOOKUP(H27,Itinerary!$B$9:$E$108,4,FALSE)="Yes","TRAVEL DAY"," ")," ") -> TRAVEL DAY
B31: {=IFERROR(_xlfn.IFS($B$8="Travel Plan",VLOOKUP(B27,Table2[],5,FALSE),$B$8="Day Plan/Activities",VLOOKUP(B27,Table2[],6,FALSE),$B$8="Today's Budget",VLOOKUP(B27,Table2[],7,FALSE),$B$8="Notes",VLOOKUP(B27,Table2[],8,FALSE))," ")} | C31: {=IFERROR(_xlfn.IFS($B$8="Travel Plan",VLOOKUP(C27,Table2[],5,FALSE),$B$8="Day Plan/Activities",VLOOKUP(C27,Table2[],6,FALSE),$B$8="Today's Budget",VLOOKUP(C27,Table2[],7,FALSE),$B$8="Notes",VLOOKUP(C27,Table2[],8,FALSE))," ")} | D31: {=IFERROR(_xlfn.IFS($B$8="Travel Plan",VLOOKUP(D27,Table2[],5,FALSE),$B$8="Day Plan/Activities",VLOOKUP(D27,Table2[],6,FALSE),$B$8="Today's Budget",VLOOKUP(D27,Table2[],7,FALSE),$B$8="Notes",VLOOKUP(D27,Table2[],8,FALSE))," ")} | E31: {=IFERROR(_xlfn.IFS($B$8="Travel Plan",VLOOKUP(E27,Table2[],5,FALSE),$B$8="Day Plan/Activities",VLOOKUP(E27,Table2[],6,FALSE),$B$8="Today's Budget",VLOOKUP(E27,Table2[],7,FALSE),$B$8="Notes",VLOOKUP(E27,Table2[],8,FALSE))," ")} | F31: {=IFERROR(_xlfn.IFS($B$8="Travel Plan",VLOOKUP(F27,Table2[],5,FALSE),$B$8="Day Plan/Activities",VLOOKUP(F27,Table2[],6,FALSE),$B$8="Today's Budget",VLOOKUP(F27,Table2[],7,FALSE),$B$8="Notes",VLOOKUP(F27,Table2[],8,FALSE))," ")} -> 0 | G31: {=IFERROR(_xlfn.IFS($B$8="Travel Plan",VLOOKUP(G27,Table2[],5,FALSE),$B$8="Day Plan/Activities",VLOOKUP(G27,Table2[],6,FALSE),$B$8="Today's Budget",VLOOKUP(G27,Table2[],7,FALSE),$B$8="Notes",VLOOKUP(G27,Table2[],8,FALSE))," ")} -> See all Gaudi Architecture | H31: {=IFERROR(_xlfn.IFS($B$8="Travel Plan",VLOOKUP(H27,Table2[],5,FALSE),$B$8="Day Plan/Activities",VLOOKUP(H27,Table2[],6,FALSE),$B$8="Today's Budget",VLOOKUP(H27,Table2[],7,FALSE),$B$8="Notes",VLOOKUP(H27,Table2[],8,FALSE))," ")} -> 0
B32: ='Itinerary-CODE'!B8 -> 45074 | C32: ='Itinerary-CODE'!C8 -> 45075 | D32: ='Itinerary-CODE'!D8 -> 45076 | E32: ='Itinerary-CODE'!E8 -> 45077 | F32: ='Itinerary-CODE'!F8 | G32: ='Itinerary-CODE'!G8 | H32: ='Itinerary-CODE'!H8
B33: =IFERROR(VLOOKUP(B32,Itinerary!$B$9:$E$108,2,FALSE)," ") -> Mallorca, Spain | C33: =IFERROR(VLOOKUP(C32,Itinerary!$B$9:$E$108,2,FALSE)," ") -> Mallorca, Spain | D33: =IFERROR(VLOOKUP(D32,Itinerary!$B$9:$E$108,2,FALSE)," ") -> Mallorca, Spain | E33: =IFERROR(VLOOKUP(E32,Itinerary!$B$9:$E$108,2,FALSE)," ") -> Ibiza, Spain | F33: =IFERROR(VLOOKUP(F32,Itinerary!$B$9:$E$108,2,FALSE)," ") | G33: =IFERROR(VLOOKUP(G32,Itinerary!$B$9:$E$108,2,FALSE)," ") | H33: =IFERROR(VLOOKUP(H32,Itinerary!$B$9:$E$108,2,FALSE)," ")
B34: =IFERROR(VLOOKUP(B32,Itinerary!$B$9:$E$108,3,FALSE)," ") -> El Josemari | C34: =IFERROR(VLOOKUP(C32,Itinerary!$B$9:$E$108,3,FALSE)," ") -> El Josemari | D34: =IFERROR(VLOOKUP(D32,Itinerary!$B$9:$E$108,3,FALSE)," ") -> El Josemari | E34: =IFERROR(VLOOKUP(E32,Itinerary!$B$9:$E$108,3,FALSE)," ") -> Amistat Ibiza | F34: =IFERROR(VLOOKUP(F32,Itinerary!$B$9:$E$108,3,FALSE)," ") | G34: =IFERROR(VLOOKUP(G32,Itinerary!$B$9:$E$108,3,FALSE)," ") | H34: =IFERROR(VLOOKUP(H32,Itinerary!$B$9:$E$108,3,FALSE)," ")
B35: =IFERROR(IF(VLOOKUP(B32,Itinerary!$B$9:$E$108,4,FALSE)="Yes","TRAVEL DAY"," ")," ") | C35: =IFERROR(IF(VLOOKUP(C32,Itinerary!$B$9:$E$108,4,FALSE)="Yes","TRAVEL DAY"," ")," ") | D35: =IFERROR(IF(VLOOKUP(D32,Itinerary!$B$9:$E$108,4,FALSE)="Yes","TRAVEL DAY"," ")," ") | E35: =IFERROR(IF(VLOOKUP(E32,Itinerary!$B$9:$E$108,4,FALSE)="Yes","TRAVEL DAY"," ")," ") -> TRAVEL DAY | F35: =IFERROR(IF(VLOOKUP(F32,Itinerary!$B$9:$E$108,4,FALSE)="Yes","TRAVEL DAY"," ")," ") | G35: =IFERROR(IF(VLOOKUP(G32,Itinerary!$B$9:$E$108,4,FALSE)="Yes","TRAVEL DAY"," ")," ") | H35: =IFERROR(IF(VLOOKUP(H32,Itinerary!$B$9:$E$108,4,FALSE)="Yes","TRAVEL DAY"," ")," ")
B36: {=IFERROR(_xlfn.IFS($B$8="Travel Plan",VLOOKUP(B32,Table2[],5,FALSE),$B$8="Day Plan/Activities",VLOOKUP(B32,Table2[],6,FALSE),$B$8="Today's Budget",VLOOKUP(B32,Table2[],7,FALSE),$B$8="Notes",VLOOKUP(B32,Table2[],8,FALSE))," ")} -> 0 | C36: {=IFERROR(_xlfn.IFS($B$8="Travel Plan",VLOOKUP(C32,Table2[],5,FALSE),$B$8="Day Plan/Activities",VLOOKUP(C32,Table2[],6,FALSE),$B$8="Today's Budget",VLOOKUP(C32,Table2[],7,FALSE),$B$8="Notes",VLOOKUP(C32,Table2[],8,FALSE))," ")} -> Day trip to Menorca | D36: {=IFERROR(_xlfn.IFS($B$8="Travel Plan",VLOOKUP(D32,Table2[],5,FALSE),$B$8="Day Plan/Activities",VLOOKUP(D32,Table2[],6,FALSE),$B$8="Today's Budget",VLOOKUP(D32,Table2[],7,FALSE),$B$8="Notes",VLOOKUP(D32,Table2[],8,FALSE))," ")} -> 0 | E36: {=IFERROR(_xlfn.IFS($B$8="Travel Plan",VLOOKUP(E32,Table2[],5,FALSE),$B$8="Day Plan/Activities",VLOOKUP(E32,Table2[],6,FALSE),$B$8="Today's Budget",VLOOKUP(E32,Table2[],7,FALSE),$B$8="Notes",VLOOKUP(E32,Table2[],8,FALSE))," ")} -> 0 | F36: {=IFERROR(_xlfn.IFS($B$8="Travel Plan",VLOOKUP(F32,Table2[],5,FALSE),$B$8="Day Plan/Activities",VLOOKUP(F32,Table2[],6,FALSE),$B$8="Today's Budget",VLOOKUP(F32,Table2[],7,FALSE),$B$8="Notes",VLOOKUP(F32,Table2[],8,FALSE))," ")} | G36: {=IFERROR(_xlfn.IFS($B$8="Travel Plan",VLOOKUP(G32,Table2[],5,FALSE),$B$8="Day Plan/Activities",VLOOKUP(G32,Table2[],6,FALSE),$B$8="Today's Budget",VLOOKUP(G32,Table2[],7,FALSE),$B$8="Notes",VLOOKUP(G32,Table2[],8,FALSE))," ")} | H36: {=IFERROR(_xlfn.IFS($B$8="Travel Plan",VLOOKUP(H32,Table2[],5,FALSE),$B$8="Day Plan/Activities",VLOOKUP(H32,Table2[],6,FALSE),$B$8="Today's Budget",VLOOKUP(H32,Table2[],7,FALSE),$B$8="Notes",VLOOKUP(H32,Table2[],8,FALSE))," ")}
B37: ='Itinerary-CODE'!B9 | C37: ='Itinerary-CODE'!C9 | E37: Notes:
B38: =IFERROR(VLOOKUP(B37,Itinerary!$B$9:$E$108,2,FALSE)," ") | C38: =IFERROR(VLOOKUP(C37,Itinerary!$B$9:$E$108,2,FALSE)," ") | D38: =IFERROR(VLOOKUP(D37,Itinerary!$B$9:$E$108,2,FALSE)," ")
B40: =IFERROR(IF(VLOOKUP(B37,Itinerary!$B$9:$E$108,4,FALSE)="Yes","TRAVEL DAY"," ")," ") | C40: =IFERROR(IF(VLOOKUP(C37,Itinerary!$B$9:$E$108,4,FALSE)="Yes","TRAVEL DAY"," ")," ") | D40: =IFERROR(IF(VLOOKUP(D37,Itinerary!$B$9:$E$108,4,FALSE)="Yes","TRAVEL DAY"," ")," ")
B42: {=(_xlfn.IFS(DreamStartMonth2=1,"January ",DreamStartMonth2=2,"February ",DreamStartMonth2=3,"March ",DreamStartMonth2=4,"April ",DreamStartMonth2=5,"May ",DreamStartMonth2=6,"June ",DreamStartMonth2=7,"July ",DreamStartMonth2=8,"August ",DreamStartMonth2=9,"September ",DreamStartMonth2=10,"October ",DreamStartMonth2=11,"November ",DreamStartMonth2=12,"December "))&YEAR(B49)} -> June 2023
B43: Sunday | C43: Monday | D43: Tuesday | E43: Wednesday | F43: Thursday | G43: Friday | H43: Saturday
...

Sheet Itinerary
B2: Itinerary - Detailed
B3: This spreadsheet is a comprehensive list of your trip!
B8: Date | C8: Location | D8: Accomodation | E8: Traveling? | F8: Travel Plan | G8: Day Plan/Activities | H8: Today's Budget | I8: Notes
B9: =DreamStartDate -> 45071 | C9: =VLOOKUP(B9,'#1 Trip Dreaming'!$K$6:$M$30,3,TRUE) -> Barcelona, Spain | D9: =IF(VLOOKUP(B9,'#2 Accomodations'!$B$7:$F$31,5,TRUE)=0," ",VLOOKUP(B9,'#2 Accomodations'!$B$7:$F$31,5,TRUE)) -> TOC Hostel Barcelona | E9: Yes | F9: Flight in from DFW early morning
B10: =B9+1 -> 45072 | C10: =VLOOKUP(B10,'#1 Trip Dreaming'!$K$6:$M$30,3,TRUE) -> Barcelona, Spain | D10: =IF(VLOOKUP(B10,'#2 Accomodations'!$B$7:$F$31,5,TRUE)=0," ",VLOOKUP(B10,'#2 Accomodations'!$B$7:$F$31,5,TRUE)) -> TOC Hostel Barcelona | E10: =IF(Table2[[#This Row],[Location]]=C9," ", "Yes") | G10: See all Gaudi Architecture
B11: =B10+1 -> 45073 | C11: =VLOOKUP(B11,'#1 Trip Dreaming'!$K$6:$M$30,3,TRUE) -> Mallorca, Spain | D11: =IF(VLOOKUP(B11,'#2 Accomodations'!$B$7:$F$31,5,TRUE)=0," ",VLOOKUP(B11,'#2 Accomodations'!$B$7:$F$31,5,TRUE)) -> El Josemari | E11: =IF(Table2[[#This Row],[Location]]=C10," ", "Yes") -> Yes | F11: Fly early morning to Mallorca
B12: =B11+1 -> 45074 | C12: =VLOOKUP(B12,'#1 Trip Dreaming'!$K$6:$M$30,3,TRUE) -> Mallorca, Spain | D12: =IF(VLOOKUP(B12,'#2 Accomodations'!$B$7:$F$31,5,TRUE)=0," ",VLOOKUP(B12,'#2 Accomodations'!$B$7:$F$31,5,TRUE)) -> El Josemari | E12: =IF(Table2[[#This Row],[Location]]=C11," ", "Yes")
B13: =B12+1 -> 45075 | C13: =VLOOKUP(B13,'#1 Trip Dreaming'!$K$6:$M$30,3,TRUE) -> Mallorca, Spain | D13: =IF(VLOOKUP(B13,'#2 Accomodations'!$B$7:$F$31,5,TRUE)=0," ",VLOOKUP(B13,'#2 Accomodations'!$B$7:$F$31,5,TRUE)) -> El Josemari | E13: =IF(Table2[[#This Row],[Location]]=C12," ", "Yes") | G13: Day trip to Menorca
B14: =B13+1 -> 45076 | C14: =VLOOKUP(B14,'#1 Trip Dreaming'!$K$6:$M$30,3,TRUE) -> Mallorca, Spain | D14: =IF(VLOOKUP(B14,'#2 Accomodations'!$B$7:$F$31,5,TRUE)=0," ",VLOOKUP(B14,'#2 Accomodations'!$B$7:$F$31,5,TRUE)) -> El Josemari | E14: =IF(Table2[[#This Row],[Location]]=C13," ", "Yes")
B15: =B14+1 -> 45077 | C15: =VLOOKUP(B15,'#1 Trip Dreaming'!$K$6:$M$30,3,TRUE) -> Ibiza, Spain | D15: =IF(VLOOKUP(B15,'#2 Accomodations'!$B$7:$F$31,5,TRUE)=0," ",VLOOKUP(B15,'#2 Accomodations'!$B$7:$F$31,5,TRUE)) -> Amistat Ibiza | E15: =IF(Table2[[#This Row],[Location]]=C14," ", "Yes") -> Yes | F15: Ferry to Ibiza?
B16: =B15+1 -> 45078 | C16: =VLOOKUP(B16,'#1 Trip Dreaming'!$K$6:$M$30,3,TRUE) -> Ibiza, Spain | D16: =IF(VLOOKUP(B16,'#2 Accomodations'!$B$7:$F$31,5,TRUE)=0," ",VLOOKUP(B16,'#2 Accomodations'!$B$7:$F$31,5,TRUE)) -> Amistat Ibiza | E16: =IF(Table2[[#This Row],[Location]]=C15," ", "Yes")
B17: =B16+1 -> 45079 | C17: =VLOOKUP(B17,'#1 Trip Dreaming'!$K$6:$M$30,3,TRUE) -> Barcelona, Spain | D17: =IF(VLOOKUP(B17,'#2 Accomodations'!$B$7:$F$31,5,TRUE)=0," ",VLOOKUP(B17,'#2 Accomodations'!$B$7:$F$31,5,TRUE)) | E17: =IF(Table2[[#This Row],[Location]]=C16," ", "Yes") -> Yes | F17: Flight back to Barca
B18: =B17+1 -> 45080 | C18: =VLOOKUP(B18,'#1 Trip Dreaming'!$K$6:$M$30,3,TRUE) | D18: =IF(VLOOKUP(B18,'#2 Accomodations'!$B$7:$F$31,5,TRUE)=0," ",VLOOKUP(B18,'#2 Accomodations'!$B$7:$F$31,5,TRUE)) | E18: =IF(Table2[[#This Row],[Location]]=C17," ", "Yes") -> Yes | F18: Fly Home!!!
B19: =B18+1 -> 45081 | C19: =VLOOKUP(B19,'#1 Trip Dreaming'!$K$6:$M$30,3,TRUE) | D19: =IF(VLOOKUP(B19,'#2 Accomodations'!$B$7:$F$31,5,TRUE)=0," ",VLOOKUP(B19,'#2 Accomodations'!$B$7:$F$31,5,TRUE)) | E19: =IF(Table2[[#This Row],[Location]]=C18," ", "Yes")
B20: =B19+1 -> 45082 | C20: =VLOOKUP(B20,'#1 Trip Dreaming'!$K$6:$M$30,3,TRUE) | D20: =IF(VLOOKUP(B20,'#2 Accomodations'!$B$7:$F$31,5,TRUE)=0," ",VLOOKUP(B20,'#2 Accomodations'!$B$7:$F$31,5,TRUE)) | E20: =IF(Table2[[#This Row],[Location]]=C19," ", "Yes")
B21: =B20+1 -> 45083 | C21: =VLOOKUP(B21,'#1 Trip Dreaming'!$K$6:$M$30,3,TRUE) | D21: =IF(VLOOKUP(B21,'#2 Accomodations'!$B$7:$F$31,5,TRUE)=0," ",VLOOKUP(B21,'#2 Accomodations'!$B$7:$F$31,5,TRUE)) | E21: =IF(Table2[[#This Row],[Location]]=C20," ", "Yes")
B22: =B21+1 -> 45084 | C22: =VLOOKUP(B22,'#1 Trip Dreaming'!$K$6:$M$30,3,TRUE) | D22: =IF(VLOOKUP(B22,'#2 Accomodations'!$B$7:$F$31,5,TRUE)=0," ",VLOOKUP(B22,'#2 Accomodations'!$B$7:$F$31,5,TRUE)) | E22: =IF(Table2[[#This Row],[Location]]=C21," ", "Yes")
B23: =B22+1 -> 45085 | C23: =VLOOKUP(B23,'#1 Trip Dreaming'!$K$6:$M$30,3,TRUE) | D23: =IF(VLOOKUP(B23,'#2 Accomodations'!$B$7:$F$31,5,TRUE)=0," ",VLOOKUP(B23,'#2 Accomodations'!$B$7:$F$31,5,TRUE)) | E23: =IF(Table2[[#This Row],[Location]]=C22," ", "Yes")
B24: =B23+1 -> 45086 | C24: =VLOOKUP(B24,'#1 Trip Dreaming'!$K$6:$M$30,3,TRUE) | D24: =IF(VLOOKUP(B24,'#2 Accomodations'!$B$7:$F$31,5,TRUE)=0," ",VLOOKUP(B24,'#2 Accomodations'!$B$7:$F$31,5,TRUE)) | E24: =IF(Table2[[#This Row],[Location]]=C23," ", "Yes")
B25: =B24+1 -> 45087 | C25: =VLOOKUP(B25,'#1 Trip Dreaming'!$K$6:$M$30,3,TRUE) | D25: =IF(VLOOKUP(B25,'#2 Accomodations'!$B$7:$F$31,5,TRUE)=0," ",VLOOKUP(B25,'#2 Accomodations'!$B$7:$F$31,5,TRUE)) | E25: =IF(Table2[[#This Row],[Location]]=C24," ", "Yes")
B26: =B25+1 -> 45088 | C26: =VLOOKUP(B26,'#1 Trip Dreaming'!$K$6:$M$30,3,TRUE) | D26: =IF(VLOOKUP(B26,'#2 Accomodations'!$B$7:$F$31,5,TRUE)=0," ",VLOOKUP(B26,'#2 Accomodations'!$B$7:$F$31,5,TRUE)) | E26: =IF(Table2[[#This Row],[Location]]=C25," ", "Yes")
B27: =B26+1 -> 45089 | C27: =VLOOKUP(B27,'#1 Trip Dreaming'!$K$6:$M$30,3,TRUE) | D27: =IF(VLOOKUP(B27,'#2 Accomodations'!$B$7:$F$31,5,TRUE)=0," ",VLOOKUP(B27,'#2 Accomodations'!$B$7:$F$31,5,TRUE)) | E27: =IF(Table2[[#This Row],[Location]]=C26," ", "Yes")
B28: =B27+1 -> 45090 | C28: =VLOOKUP(B28,'#1 Trip Dreaming'!$K$6:$M$30,3,TRUE) | D28: =IF(VLOOKUP(B28,'#2 Accomodations'!$B$7:$F$31,5,TRUE)=0," ",VLOOKUP(B28,'#2 Accomodations'!$B$7:$F$31,5,TRUE)) | E28: =IF(Table2[[#This Row],[Location]]=C27," ", "Yes")
B29: =B28+1 -> 45091 | C29: =VLOOKUP(B29,'#1 Trip Dreaming'!$K$6:$M$30,3,TRUE) | D29: =IF(VLOOKUP(B29,'#2 Accomodations'!$B$7:$F$31,5,TRUE)=0," ",VLOOKUP(B29,'#2 Accomodations'!$B$7:$F$31,5,TRUE)) | E29: =IF(Table2[[#This Row],[Location]]=C28," ", "Yes")
B30: =B29+1 -> 45092 | C30: =VLOOKUP(B30,'#1 Trip Dreaming'!$K$6:$M$30,3,TRUE) | D30: =IF(VLOOKUP(B30,'#2 Accomodations'!$B$7:$F$31,5,TRUE)=0," ",VLOOKUP(B30,'#2 Accomodations'!$B$7:$F$31,5,TRUE)) | E30: =IF(Table2[[#This Row],[Location]]=C29," ", "Yes")
... B108: =B107+1 -> 45170 | C108: =VLOOKUP(B108,'#1 Trip Dreaming'!$K$6:$M$30,3,TRUE) | D108: =IF(VLOOKUP(B108,'#2 Accomodations'!$B$7:$F$31,5,TRUE)=0," ",VLOOKUP(B108,'#2 Accomodations'!$B$7:$F$31,5,TRUE)) | E108: =IF(Table2[[#This Row],[Location]]=C107," ", "Yes")

Sheet Itinerary-CODE
B2: =MONTH(DreamStartDate) -> 5
B3: Sunday | C3: Monday | D3: Tuesday | E3: Wednesday | F3: Thursday | G3: Friday | H3: Saturday
A4: Month 1 | B4: {=IF(MONTH(DATE(YEAR(DreamStartDate),MONTH(DreamStartDate),1))- MONTH(DATE(YEAR(DreamStartDate),MONTH(DreamStartDate),1)- (WEEKDAY(DATE(YEAR(DreamStartDate),MONTH(DreamStartDate),1))-1)+ {0;1;2;3;4;5}*7+{1,2,3,4,5,6,7}-1),"",DATE(YEAR(DreamStartDate), MONTH(DreamStartDate),1)-(WEEKDAY(DATE(YEAR(DreamStartDate), MONTH(DreamStartDate),1))-1)+{0;1;2;3;4;5}*7+{1,2,3,4,5,6,7}-1)} | C4: 45047 | D4: 45048 | E4: 45049 | F4: 45050 | G4: 45051 | H4: 45052
B5: 45053 | C5: 45054 | D5: 45055 | E5: 45056 | F5: 45057 | G5: 45058 | H5: 45059
B6: 45060 | C6: 45061 | D6: 45062 | E6: 45063 | F6: 45064 | G6: 45065 | H6: 45066
B7: 45067 | C7: 45068 | D7: 45069 | E7: 45070 | F7: 45071 | G7: 45072 | H7: 45073
B8: 45074 | C8: 45075 | D8: 45076 | E8: 45077
A10: Month 2 | B10: {=IF(MONTH(DATE(YEAR(DreamStartDate),DreamStartMonth+1,1))- MONTH(DATE(YEAR(DreamStartDate),DreamStartMonth+1,1)- (WEEKDAY(DATE(YEAR(DreamStartDate),DreamStartMonth+1,1))-1)+ {0;1;2;3;4;5}*7+{1,2,3,4,5,6,7}-1),"",DATE(YEAR(DreamStartDate), DreamStartMonth+1,1)-(WEEKDAY(DATE(YEAR(DreamStartDate), DreamStartMonth+1,1))-1)+{0;1;2;3;4;5}*7+{1,2,3,4,5,6,7}-1)} | F10: 45078 | G10: 45079 | H10: 45080
B11: 45081 | C11: 45082 | D11: 45083 | E11: 45084 | F11: 45085 | G11: 45086 | H11: 45087
B12: 45088 | C12: 45089 | D12: 45090 | E12: 45091 | F12: 45092 | G12: 45093 | H12: 45094
B13: 45095 | C13: 45096 | D13: 45097 | E13: 45098 | F13: 45099 | G13: 45100 | H13: 45101
B14: 45102 | C14: 45103 | D14: 45104 | E14: 45105 | F14: 45106 | G14: 45107
A16: Month 3 | B16: {=IF(MONTH(DATE(YEAR(DreamStartDate),DreamStartMonth+2,1))- MONTH(DATE(YEAR(DreamStartDate),DreamStartMonth+2,1)- (WEEKDAY(DATE(YEAR(DreamStartDate),DreamStartMonth+2,1))-1)+ {0;1;2;3;4;5}*7+{1,2,3,4,5,6,7}-1),"",DATE(YEAR(DreamStartDate), DreamStartMonth+2,1)-(WEEKDAY(DATE(YEAR(DreamStartDate), DreamStartMonth+2,1))-1)+{0;1;2;3;4;5}*7+{1,2,3,4,5,6,7}-1)} | H16: 45108
B17: 45109 | C17: 45110 | D17: 45111 | E17: 45112 | F17: 45113 | G17: 45114 | H17: 45115
B18: 45116 | C18: 45117 | D18: 45118 | E18: 45119 | F18: 45120 | G18: 45121 | H18: 45122
B19: 45123 | C19: 45124 | D19: 45125 | E19: 45126 | F19: 45127 | G19: 45128 | H19: 45129
B20: 45130 | C20: 45131 | D20: 45132 | E20: 45133 | F20: 45134 | G20: 45135 | H20: 45136
B21: 45137 | C21: 45138

Sheet #2 Accomodations
B2: Accomodations | F2: Total Accomodation Cost (Booked) | J2: % Booked
B3: The hostels, airbnbs, tents?, boats, and other places you will be staying! | F3: =SUM(I7:I31) -> 270 | J3: =COUNTIF(J7:J31,"Yes")/COUNTA(F7:F31) -> 0
B4: This data feeds into the itinerary!
B6: Check-In Date | C6: Check-Out Date | D6: Location | E6: # of Days | F6: Name | G6: $ Per Night | H6: $ All Nights | I6: Total Booked Cost | J6: Booked? | K6: Booking Site | L6: Cash or Card
B7: ='#1 Trip Dreaming'!K6 -> 45071 | C7: ='#1 Trip Dreaming'!L6 -> 45073 | D7: ='#1 Trip Dreaming'!M6 -> Barcelona, Spain | E7: =IF('#1 Trip Dreaming'!N6=0," ",'#1 Trip Dreaming'!N6) -> 2 | F7: TOC Hostel Barcelona | H7: 50 | I7: 50
B8: ='#1 Trip Dreaming'!K7 -> 45073 | C8: ='#1 Trip Dreaming'!L7 -> 45077 | D8: ='#1 Trip Dreaming'!M7 -> Mallorca, Spain | E8: =IF('#1 Trip Dreaming'!N7=0," ",'#1 Trip Dreaming'!N7) -> 4 | F8: El Josemari | H8: 220 | I8: 220
B9: ='#1 Trip Dreaming'!K8 -> 45077 | C9: ='#1 Trip Dreaming'!L8 -> 45079 | D9: ='#1 Trip Dreaming'!M8 -> Ibiza, Spain | E9: =IF('#1 Trip Dreaming'!N8=0," ",'#1 Trip Dreaming'!N8) -> 2 | F9: Amistat Ibiza
B10: ='#1 Trip Dreaming'!K9 -> 45079 | C10: ='#1 Trip Dreaming'!L9 -> 45080 | D10: ='#1 Trip Dreaming'!M9 -> Barcelona, Spain | E10: =IF('#1 Trip Dreaming'!N9=0," ",'#1 Trip Dreaming'!N9) -> 1
B11: ='#1 Trip Dreaming'!K10 -> 45080 | C11: ='#1 Trip Dreaming'!L10 -> 45080 | D11: ='#1 Trip Dreaming'!M10 | E11: =IF('#1 Trip Dreaming'!N10=0," ",'#1 Trip Dreaming'!N10)
B12: ='#1 Trip Dreaming'!K11 | C12: ='#1 Trip Dreaming'!L11 | D12: ='#1 Trip Dreaming'!M11 | E12: =IF('#1 Trip Dreaming'!N11=0," ",'#1 Trip Dreaming'!N11)
B13: ='#1 Trip Dreaming'!K12 | C13: ='#1 Trip Dreaming'!L12 | D13: ='#1 Trip Dreaming'!M12 | E13: =IF('#1 Trip Dreaming'!N12=0," ",'#1 Trip Dreaming'!N12)
B14: ='#1 Trip Dreaming'!K13 | C14: ='#1 Trip Dreaming'!L13 | D14: ='#1 Trip Dreaming'!M13 | E14: =IF('#1 Trip Dreaming'!N13=0," ",'#1 Trip Dreaming'!N13)
B15: ='#1 Trip Dreaming'!K14 | C15: ='#1 Trip Dreaming'!L14 | D15: ='#1 Trip Dreaming'!M14 | E15: =IF('#1 Trip Dreaming'!N14=0," ",'#1 Trip Dreaming'!N14)
B16: ='#1 Trip Dreaming'!K15 | C16: ='#1 Trip Dreaming'!L15 | D16: ='#1 Trip Dreaming'!M15 | E16: =IF('#1 Trip Dreaming'!N15=0," ",'#1 Trip Dreaming'!N15)
B17: ='#1 Trip Dreaming'!K16 | C17: ='#1 Trip Dreaming'!L16 | D17: ='#1 Trip Dreaming'!M16 | E17: =IF('#1 Trip Dreaming'!N16=0," ",'#1 Trip Dreaming'!N16)
B18: ='#1 Trip Dreaming'!K17 | C18: ='#1 Trip Dreaming'!L17 | D18: ='#1 Trip Dreaming'!M17 | E18: =IF('#1 Trip Dreaming'!N17=0," ",'#1 Trip Dreaming'!N17)
B19: ='#1 Trip Dreaming'!K18 | C19: ='#1 Trip Dreaming'!L18 | D19: ='#1 Trip Dreaming'!M18 | E19: =IF('#1 Trip Dreaming'!N18=0," ",'#1 Trip Dreaming'!N18)
B20: ='#1 Trip Dreaming'!K19 | C20: ='#1 Trip Dreaming'!L19 | D20: ='#1 Trip Dreaming'!M19 | E20: =IF('#1 Trip Dreaming'!N19=0," ",'#1 Trip Dreaming'!N19)
B21: ='#1 Trip Dreaming'!K20 | C21: ='#1 Trip Dreaming'!L20 | D21: ='#1 Trip Dreaming'!M20 | E21: =IF('#1 Trip Dreaming'!N20=0," ",'#1 Trip Dreaming'!N20)
... B31: ='#1 Trip Dreaming'!K30 | C31: ='#1 Trip Dreaming'!L30 | D31: ='#1 Trip Dreaming'!M30 | E31: =IF('#1 Trip Dreaming'!N30=0," ",'#1 Trip Dreaming'!N30)

Sheet #3 Transportation
B2: Transportation | H2: Total Transportation Cost
B3: What days you are traveling and how! This data doesn’t go anywhere it's just for organization. | H3: =SUM(G7:G32) -> 1560
B6: Date | C6: From | D6: To | E6: Via | F6: Carrier | G6: Cost $$$ | H6: Roundtrip/Oneway/Unlimited | I6: Reservation # | J6: Confirmation #
B7: 45070 | C7: DFW | D7: Barcelona | E7: Flight | F7: AA | G7: 1430 | H7: Roundtrip
B8: 45073 | C8: Barcelona | D8: Majorca | E8: Flight | F8: Vueling | G8: 130 | H8: Oneway

Sheet #4 Building a Budget
B2: Trip Budget - I already have something in mind… | M2: Trip Budget
B3: You already know how much you plan on spending for these categories | M3: Here's a little help coming up with a budget for your trip
B5: Total Spending Limit | M5: Total Spending Limit
B6: this is the sum of the categories below. | I6: =SUM(I8,I10,I13,I15,I17,I19) -> 1500 | M6: this is the abslute max you can spend. | T6: 2500 | Z6: Travel | AA6: =T8 -> 1560
B7: Travel | M7: Travel | Z7: Accomodations | AA7: =T10 -> 270
B8: flights, trains, passes, bus tickets, rental cars. | I8: 1500 | M8: flights, trains, passes, bus tickets, rental cars. | T8: =SUM('#3 Transportation'!H3) -> 1560 | Z8: Food | AA8: =T13 -> 135
B9: Accomodations | M9: Accomodations | Z9: Activities | AA9: =T15 -> 200
B10: hostels, hotel rooms, airbnbs, house boats | M10: hostels, hotel rooms, airbnbs, house boats | T10: ='#2 Accomodations'!F3 -> 270 | Z10: Spending Money | AA10: =T17 -> 100
B11: Food | M11: Food | Z11: Safety Money | AA11: =T19 -> 0
B12: daily food budget | M12: daily food budget | T12: 15 | Z12: Leftover Budget | AA12: =Q23 -> 235
B13: food budget for the whole trip | M13: food budget for the whole trip | T13: =T12*'#1 Trip Dreaming'!L3 -> 135
B14: Activities | M14: Activities
B15: tours, skydiving, entry fees, museums, cooking classes | M15: tours, skydiving, entry fees, museums, cooking classes | T15: 200
B16: Spending Money | M16: Spending Money
B17: extra cash to have on hand to purchase whatever your heart desires | M17: extra cash to have on hand to purchase whatever your heart desires | T17: 100
B18: Safety Money | M18: Safety Money
B19: backup cash to get a flight home / hospital bills | M19: backup cash to get a flight home / anything crazy
N23: This is what is left in the budget: | Q23: =T6-SUM(T8,T10,T13,T15,T17,T19) -> 235

Sheet #5 Packing List
B2: Packing List & Checklist | F2: Undies | J2: Miscellaneous
B3: Keep track of everything you plan on bringing | F3: Item | G3: Qty | J3: Item | K3: Qty
F4: Calvin Klien bralette | G4: 3 | J4: 55L backpack | K4: 1
B5: Clothes | F5: Panties | G5: 16 | J5: Packing cubes | K5: 6
B6: Item | C6: Qty | F6: Sports bra | G6: 3 | J6: Miniature gorilla tripod | K6: 1
B7: Levi's jeans (black & denim) | C7: 2 | F7: Regular socks | G7: 4 | J7: microfiber towel | K7: 1
B8: Jean shorts | C8: 1 | F8: Hiking socks | G8: 2 | J8: toothbrush for dirty shoes | K8: 1
B9: Black polka dot skirt | C9: 1 | J9: dirty clothes bag | K9: 1
B10: Blazers (leather & check) | C10: 2 | J10: dirty shoes back | K10: 1
B11: Down jacket | C11: 1 | J11: laundry detergent | K11: 1
B12: graphic tee | C12: 2 | J12: fanny pack | K12: 1
B13: high neck bramis (black, grey, & pink) | C13: 3 | F13: Technology | J13: tote bag | K13: 1
B14: tank top (navy & black) | C14: 2 | F14: Item | G14: Qty
B15: going out tops | C15: 3 | F15: Phone charger | G15: 1
B16: black turtleneck | C16: 1 | F16: Laptop & charger | G16: 1
B17: black romper | C17: 1 | F17: Portable charger | G17: 2
B18: black maxi dress | C18: 1 | F18: Power outlet adapter (EU & UK) | G18: 2 | J18: Toiletries & Medications
B19: Black running shorts | C19: 1 | F19: Bluetooth camera button | G19: 1 | J19: Item | K19: Qty
B20: Navy biker shorts | C20: 1 | F20: airpods | G20: 1 | J20: shampoo | K20: 1
B21: longsleeve running shirt | C21: 1 | F21: digital camera & charger | G21: 1 | J21: conditioner | K21: 2
B22: shortsleeve running shirt | C22: 1 | J22: leave in conditioner | K22: 1
B23: rain jacket | J23: face wash | K23: 1
J24: moisturizer | K24: 1
J25: sunscreen | K25: 1
J26: bar of soap | K26: 1
F27: Shoes | J27: toothbrush | K27: 1
F28: Item | G28: Qty | J28: toothpaste | K28: 1
F29: Veja sneakers | G29: 1 | J29: nausea medicine
F30: Waterproof birkenstocks | G30: 1 | J30: sleep aid
F31: Hiking shoes | G31: 1 | J31: advil

Sheet #6 Booking Checklist
B2: Planning Checklist
B3: Keep track of everything you have booked and need to book!
B5: Accomodations | F5: Transportation | J5: Experiences & Miscellaneous
B6: Item | C6: Due Date | F6: Item | G6: Due Date | J6: Item | K6: Due Date
B7: Hotel #1 | C7: 45087 | F7: Flight #1 | J7: Wine tour
B8: Hostel #2 | F8: Train Pass | J8: Sound of Music Experience
B9: House Boat #3 | F9: Ferry | J9: Ann Frank Museum
B10: Yurt #4 | F10: Rental Car | J10: Pack Backpack
B11: Airbnb #5 | J11: Buy toiletries
B12: Couch #6

Sheet Plan Checklist
